[2022-04-19 15:39:19,742] {taskinstance.py:851} INFO - Dependencies all met for <TaskInstance: analyze_json_data.saveToDB 2022-04-19T15:37:11.698593+00:00 [queued]>
[2022-04-19 15:39:19,748] {taskinstance.py:851} INFO - Dependencies all met for <TaskInstance: analyze_json_data.saveToDB 2022-04-19T15:37:11.698593+00:00 [queued]>
[2022-04-19 15:39:19,748] {taskinstance.py:1042} INFO - 
--------------------------------------------------------------------------------
[2022-04-19 15:39:19,748] {taskinstance.py:1043} INFO - Starting attempt 4 of 4
[2022-04-19 15:39:19,748] {taskinstance.py:1044} INFO - 
--------------------------------------------------------------------------------
[2022-04-19 15:39:19,758] {taskinstance.py:1063} INFO - Executing <Task(PythonOperator): saveToDB> on 2022-04-19T15:37:11.698593+00:00
[2022-04-19 15:39:19,762] {standard_task_runner.py:52} INFO - Started process 1369 to run task
[2022-04-19 15:39:19,764] {standard_task_runner.py:76} INFO - Running: ['airflow', 'tasks', 'run', 'analyze_json_data', 'saveToDB', '2022-04-19T15:37:11.698593+00:00', '--job-id', '278', '--pool', 'default_pool', '--raw', '--subdir', 'DAGS_FOLDER/dagRun.py', '--cfg-path', '/tmp/tmpgtujlicx', '--error-file', '/tmp/tmpgs21ugd9']
[2022-04-19 15:39:19,766] {standard_task_runner.py:77} INFO - Job 278: Subtask saveToDB
[2022-04-19 15:39:19,795] {logging_mixin.py:104} INFO - Running <TaskInstance: analyze_json_data.saveToDB 2022-04-19T15:37:11.698593+00:00 [running]> on host 1189a6233bd7
[2022-04-19 15:39:19,824] {taskinstance.py:1257} INFO - Exporting the following env vars:
AIRFLOW_CTX_DAG_OWNER=Renato_Otescu
AIRFLOW_CTX_DAG_ID=analyze_json_data
AIRFLOW_CTX_TASK_ID=saveToDB
AIRFLOW_CTX_EXECUTION_DATE=2022-04-19T15:37:11.698593+00:00
AIRFLOW_CTX_DAG_RUN_ID=manual__2022-04-19T15:37:11.698593+00:00
[2022-04-19 15:39:19,853] {base_aws.py:362} INFO - Airflow Connection: aws_conn_id=aws_default
[2022-04-19 15:39:19,854] {crypto.py:82} WARNING - empty cryptography key - values will not be stored encrypted.
[2022-04-19 15:39:19,854] {base_aws.py:171} INFO - Credentials retrieved from extra_config['s3_config_file']
[2022-04-19 15:39:19,854] {base_aws.py:81} INFO - Creating session with aws_access_key_id=AKIA2RNRZHIUSS5EYBCG region_name=None
[2022-04-19 15:39:19,862] {base_aws.py:151} INFO - role_arn is None
[2022-04-19 15:39:21,893] {taskinstance.py:1455} ERROR - S3ServiceException:Access Denied,Status 403,Error AccessDenied,Rid 1A7W3745YWPWG3N4,ExtRid WytrdCpqsaycSjKxHIeR6KTz6d4CXHrfIREjpuC9jTSOVvzj6NnyWHNSEIi6H85tUm9ZeZWzOwc=,CanRetry 1
DETAIL:  
  -----------------------------------------------
  error:  S3ServiceException:Access Denied,Status 403,Error AccessDenied,Rid 1A7W3745YWPWG3N4,ExtRid WytrdCpqsaycSjKxHIeR6KTz6d4CXHrfIREjpuC9jTSOVvzj6NnyWHNSEIi6H85tUm9ZeZWzOwc=,CanRetry 1
  code:      8001
  context:   S3 key being read : s3://airflow-raw/results.csv
  query:     193455
  location:  copy_s3_scanner.cpp:301
  process:   query0_126_193455 [pid=16513]
  -----------------------------------------------

Traceback (most recent call last):
  File "/home/airflow/.local/lib/python3.6/site-packages/airflow/models/taskinstance.py", line 1112, in _run_raw_task
    self._prepare_and_execute_task_with_callbacks(context, task)
  File "/home/airflow/.local/lib/python3.6/site-packages/airflow/models/taskinstance.py", line 1285, in _prepare_and_execute_task_with_callbacks
    result = self._execute_task(context, task_copy)
  File "/home/airflow/.local/lib/python3.6/site-packages/airflow/models/taskinstance.py", line 1315, in _execute_task
    result = task_copy.execute(context=context)
  File "/home/airflow/.local/lib/python3.6/site-packages/airflow/operators/python.py", line 117, in execute
    return_value = self.execute_callable()
  File "/home/airflow/.local/lib/python3.6/site-packages/airflow/operators/python.py", line 128, in execute_callable
    return self.python_callable(*self.op_args, **self.op_kwargs)
  File "/opt/airflow/dags/dagRun.py", line 270, in uploadToDB
    cursor.execute(sql)
psycopg2.errors.InternalError_: S3ServiceException:Access Denied,Status 403,Error AccessDenied,Rid 1A7W3745YWPWG3N4,ExtRid WytrdCpqsaycSjKxHIeR6KTz6d4CXHrfIREjpuC9jTSOVvzj6NnyWHNSEIi6H85tUm9ZeZWzOwc=,CanRetry 1
DETAIL:  
  -----------------------------------------------
  error:  S3ServiceException:Access Denied,Status 403,Error AccessDenied,Rid 1A7W3745YWPWG3N4,ExtRid WytrdCpqsaycSjKxHIeR6KTz6d4CXHrfIREjpuC9jTSOVvzj6NnyWHNSEIi6H85tUm9ZeZWzOwc=,CanRetry 1
  code:      8001
  context:   S3 key being read : s3://airflow-raw/results.csv
  query:     193455
  location:  copy_s3_scanner.cpp:301
  process:   query0_126_193455 [pid=16513]
  -----------------------------------------------


[2022-04-19 15:39:21,895] {taskinstance.py:1503} INFO - Marking task as FAILED. dag_id=analyze_json_data, task_id=saveToDB, execution_date=20220419T153711, start_date=20220419T153919, end_date=20220419T153921
[2022-04-19 15:39:21,939] {local_task_job.py:146} INFO - Task exited with return code 1
