[2022-05-07 14:15:05,322] {taskinstance.py:851} INFO - Dependencies all met for <TaskInstance: analyze_json_data.saveToDB 2022-05-02T00:00:00+00:00 [queued]>
[2022-05-07 14:15:05,327] {taskinstance.py:851} INFO - Dependencies all met for <TaskInstance: analyze_json_data.saveToDB 2022-05-02T00:00:00+00:00 [queued]>
[2022-05-07 14:15:05,328] {taskinstance.py:1042} INFO - 
--------------------------------------------------------------------------------
[2022-05-07 14:15:05,328] {taskinstance.py:1043} INFO - Starting attempt 2 of 4
[2022-05-07 14:15:05,328] {taskinstance.py:1044} INFO - 
--------------------------------------------------------------------------------
[2022-05-07 14:15:05,338] {taskinstance.py:1063} INFO - Executing <Task(PythonOperator): saveToDB> on 2022-05-02T00:00:00+00:00
[2022-05-07 14:15:05,341] {standard_task_runner.py:52} INFO - Started process 1262 to run task
[2022-05-07 14:15:05,343] {standard_task_runner.py:76} INFO - Running: ['airflow', 'tasks', 'run', 'analyze_json_data', 'saveToDB', '2022-05-02T00:00:00+00:00', '--job-id', '306', '--pool', 'default_pool', '--raw', '--subdir', 'DAGS_FOLDER/dagRun.py', '--cfg-path', '/tmp/tmp1yki58w6', '--error-file', '/tmp/tmpbsgrbwd7']
[2022-05-07 14:15:05,346] {standard_task_runner.py:77} INFO - Job 306: Subtask saveToDB
[2022-05-07 14:15:05,376] {logging_mixin.py:104} INFO - Running <TaskInstance: analyze_json_data.saveToDB 2022-05-02T00:00:00+00:00 [running]> on host 1189a6233bd7
[2022-05-07 14:15:05,403] {taskinstance.py:1257} INFO - Exporting the following env vars:
AIRFLOW_CTX_DAG_OWNER=Renato_Otescu
AIRFLOW_CTX_DAG_ID=analyze_json_data
AIRFLOW_CTX_TASK_ID=saveToDB
AIRFLOW_CTX_EXECUTION_DATE=2022-05-02T00:00:00+00:00
AIRFLOW_CTX_DAG_RUN_ID=scheduled__2022-05-02T00:00:00+00:00
[2022-05-07 14:15:05,434] {base_aws.py:362} INFO - Airflow Connection: aws_conn_id=aws_default
[2022-05-07 14:15:05,434] {crypto.py:82} WARNING - empty cryptography key - values will not be stored encrypted.
[2022-05-07 14:15:05,435] {base_aws.py:171} INFO - Credentials retrieved from extra_config['s3_config_file']
[2022-05-07 14:15:05,435] {base_aws.py:81} INFO - Creating session with aws_access_key_id=AKIA2RNRZHIUSS5EYBCG region_name=None
[2022-05-07 14:15:05,448] {base_aws.py:151} INFO - role_arn is None
[2022-05-07 14:15:07,043] {taskinstance.py:1455} ERROR - S3ServiceException:Access Denied,Status 403,Error AccessDenied,Rid 1KG8RFHT063EDH4F,ExtRid qLtvBCwVstxe+SWSWLkR3wFyVM3EdLzLOAYRLXhEys5l1MNkyBloYAW1mKOC6ou13zbLqHPkOxg=,CanRetry 1
DETAIL:  
  -----------------------------------------------
  error:  S3ServiceException:Access Denied,Status 403,Error AccessDenied,Rid 1KG8RFHT063EDH4F,ExtRid qLtvBCwVstxe+SWSWLkR3wFyVM3EdLzLOAYRLXhEys5l1MNkyBloYAW1mKOC6ou13zbLqHPkOxg=,CanRetry 1
  code:      8001
  context:   S3 key being read : s3://airflow-raw/results.csv
  query:     473140
  location:  copy_s3_scanner.cpp:301
  process:   query0_125_473140 [pid=3137]
  -----------------------------------------------

Traceback (most recent call last):
  File "/home/airflow/.local/lib/python3.6/site-packages/airflow/models/taskinstance.py", line 1112, in _run_raw_task
    self._prepare_and_execute_task_with_callbacks(context, task)
  File "/home/airflow/.local/lib/python3.6/site-packages/airflow/models/taskinstance.py", line 1285, in _prepare_and_execute_task_with_callbacks
    result = self._execute_task(context, task_copy)
  File "/home/airflow/.local/lib/python3.6/site-packages/airflow/models/taskinstance.py", line 1315, in _execute_task
    result = task_copy.execute(context=context)
  File "/home/airflow/.local/lib/python3.6/site-packages/airflow/operators/python.py", line 117, in execute
    return_value = self.execute_callable()
  File "/home/airflow/.local/lib/python3.6/site-packages/airflow/operators/python.py", line 128, in execute_callable
    return self.python_callable(*self.op_args, **self.op_kwargs)
  File "/opt/airflow/dags/dagRun.py", line 270, in uploadToDB
    cursor.execute(sql)
psycopg2.errors.InternalError_: S3ServiceException:Access Denied,Status 403,Error AccessDenied,Rid 1KG8RFHT063EDH4F,ExtRid qLtvBCwVstxe+SWSWLkR3wFyVM3EdLzLOAYRLXhEys5l1MNkyBloYAW1mKOC6ou13zbLqHPkOxg=,CanRetry 1
DETAIL:  
  -----------------------------------------------
  error:  S3ServiceException:Access Denied,Status 403,Error AccessDenied,Rid 1KG8RFHT063EDH4F,ExtRid qLtvBCwVstxe+SWSWLkR3wFyVM3EdLzLOAYRLXhEys5l1MNkyBloYAW1mKOC6ou13zbLqHPkOxg=,CanRetry 1
  code:      8001
  context:   S3 key being read : s3://airflow-raw/results.csv
  query:     473140
  location:  copy_s3_scanner.cpp:301
  process:   query0_125_473140 [pid=3137]
  -----------------------------------------------


[2022-05-07 14:15:07,045] {taskinstance.py:1503} INFO - Marking task as UP_FOR_RETRY. dag_id=analyze_json_data, task_id=saveToDB, execution_date=20220502T000000, start_date=20220507T141505, end_date=20220507T141507
[2022-05-07 14:15:07,078] {local_task_job.py:146} INFO - Task exited with return code 1
