[2022-05-07 14:15:38,520] {taskinstance.py:851} INFO - Dependencies all met for <TaskInstance: analyze_json_data.saveToDB 2022-05-02T00:00:00+00:00 [queued]>
[2022-05-07 14:15:38,526] {taskinstance.py:851} INFO - Dependencies all met for <TaskInstance: analyze_json_data.saveToDB 2022-05-02T00:00:00+00:00 [queued]>
[2022-05-07 14:15:38,526] {taskinstance.py:1042} INFO - 
--------------------------------------------------------------------------------
[2022-05-07 14:15:38,526] {taskinstance.py:1043} INFO - Starting attempt 3 of 4
[2022-05-07 14:15:38,526] {taskinstance.py:1044} INFO - 
--------------------------------------------------------------------------------
[2022-05-07 14:15:38,536] {taskinstance.py:1063} INFO - Executing <Task(PythonOperator): saveToDB> on 2022-05-02T00:00:00+00:00
[2022-05-07 14:15:38,540] {standard_task_runner.py:52} INFO - Started process 1590 to run task
[2022-05-07 14:15:38,543] {standard_task_runner.py:76} INFO - Running: ['airflow', 'tasks', 'run', 'analyze_json_data', 'saveToDB', '2022-05-02T00:00:00+00:00', '--job-id', '308', '--pool', 'default_pool', '--raw', '--subdir', 'DAGS_FOLDER/dagRun.py', '--cfg-path', '/tmp/tmpwu8xts3_', '--error-file', '/tmp/tmp1fv440qr']
[2022-05-07 14:15:38,545] {standard_task_runner.py:77} INFO - Job 308: Subtask saveToDB
[2022-05-07 14:15:38,579] {logging_mixin.py:104} INFO - Running <TaskInstance: analyze_json_data.saveToDB 2022-05-02T00:00:00+00:00 [running]> on host 1189a6233bd7
[2022-05-07 14:15:38,610] {taskinstance.py:1257} INFO - Exporting the following env vars:
AIRFLOW_CTX_DAG_OWNER=Renato_Otescu
AIRFLOW_CTX_DAG_ID=analyze_json_data
AIRFLOW_CTX_TASK_ID=saveToDB
AIRFLOW_CTX_EXECUTION_DATE=2022-05-02T00:00:00+00:00
AIRFLOW_CTX_DAG_RUN_ID=scheduled__2022-05-02T00:00:00+00:00
[2022-05-07 14:15:38,640] {base_aws.py:362} INFO - Airflow Connection: aws_conn_id=aws_default
[2022-05-07 14:15:38,641] {crypto.py:82} WARNING - empty cryptography key - values will not be stored encrypted.
[2022-05-07 14:15:38,642] {base_aws.py:171} INFO - Credentials retrieved from extra_config['s3_config_file']
[2022-05-07 14:15:38,642] {base_aws.py:81} INFO - Creating session with aws_access_key_id=AKIA2RNRZHIUSS5EYBCG region_name=None
[2022-05-07 14:15:38,652] {base_aws.py:151} INFO - role_arn is None
[2022-05-07 14:15:40,330] {taskinstance.py:1455} ERROR - S3ServiceException:Access Denied,Status 403,Error AccessDenied,Rid A85WVYH4PWZC07QJ,ExtRid F92tAm6vq/jUdNraA90lyZAex2eRIRulxdTjSYjVGBluRbyafq4Mox/Yq1GbRqQGPmFCon6oGdo=,CanRetry 1
DETAIL:  
  -----------------------------------------------
  error:  S3ServiceException:Access Denied,Status 403,Error AccessDenied,Rid A85WVYH4PWZC07QJ,ExtRid F92tAm6vq/jUdNraA90lyZAex2eRIRulxdTjSYjVGBluRbyafq4Mox/Yq1GbRqQGPmFCon6oGdo=,CanRetry 1
  code:      8001
  context:   S3 key being read : s3://airflow-raw/results.csv
  query:     473143
  location:  copy_s3_scanner.cpp:301
  process:   query0_124_473143 [pid=3123]
  -----------------------------------------------

Traceback (most recent call last):
  File "/home/airflow/.local/lib/python3.6/site-packages/airflow/models/taskinstance.py", line 1112, in _run_raw_task
    self._prepare_and_execute_task_with_callbacks(context, task)
  File "/home/airflow/.local/lib/python3.6/site-packages/airflow/models/taskinstance.py", line 1285, in _prepare_and_execute_task_with_callbacks
    result = self._execute_task(context, task_copy)
  File "/home/airflow/.local/lib/python3.6/site-packages/airflow/models/taskinstance.py", line 1315, in _execute_task
    result = task_copy.execute(context=context)
  File "/home/airflow/.local/lib/python3.6/site-packages/airflow/operators/python.py", line 117, in execute
    return_value = self.execute_callable()
  File "/home/airflow/.local/lib/python3.6/site-packages/airflow/operators/python.py", line 128, in execute_callable
    return self.python_callable(*self.op_args, **self.op_kwargs)
  File "/opt/airflow/dags/dagRun.py", line 270, in uploadToDB
    cursor.execute(sql)
psycopg2.errors.InternalError_: S3ServiceException:Access Denied,Status 403,Error AccessDenied,Rid A85WVYH4PWZC07QJ,ExtRid F92tAm6vq/jUdNraA90lyZAex2eRIRulxdTjSYjVGBluRbyafq4Mox/Yq1GbRqQGPmFCon6oGdo=,CanRetry 1
DETAIL:  
  -----------------------------------------------
  error:  S3ServiceException:Access Denied,Status 403,Error AccessDenied,Rid A85WVYH4PWZC07QJ,ExtRid F92tAm6vq/jUdNraA90lyZAex2eRIRulxdTjSYjVGBluRbyafq4Mox/Yq1GbRqQGPmFCon6oGdo=,CanRetry 1
  code:      8001
  context:   S3 key being read : s3://airflow-raw/results.csv
  query:     473143
  location:  copy_s3_scanner.cpp:301
  process:   query0_124_473143 [pid=3123]
  -----------------------------------------------


[2022-05-07 14:15:40,332] {taskinstance.py:1503} INFO - Marking task as UP_FOR_RETRY. dag_id=analyze_json_data, task_id=saveToDB, execution_date=20220502T000000, start_date=20220507T141538, end_date=20220507T141540
[2022-05-07 14:15:40,357] {local_task_job.py:146} INFO - Task exited with return code 1
