[2022-06-18 15:12:48,810] {taskinstance.py:851} INFO - Dependencies all met for <TaskInstance: analyze_json_data.saveToDB 2022-06-17T00:00:00+00:00 [queued]>
[2022-06-18 15:12:48,820] {taskinstance.py:851} INFO - Dependencies all met for <TaskInstance: analyze_json_data.saveToDB 2022-06-17T00:00:00+00:00 [queued]>
[2022-06-18 15:12:48,820] {taskinstance.py:1042} INFO - 
--------------------------------------------------------------------------------
[2022-06-18 15:12:48,821] {taskinstance.py:1043} INFO - Starting attempt 4 of 4
[2022-06-18 15:12:48,821] {taskinstance.py:1044} INFO - 
--------------------------------------------------------------------------------
[2022-06-18 15:12:48,826] {taskinstance.py:1063} INFO - Executing <Task(PythonOperator): saveToDB> on 2022-06-17T00:00:00+00:00
[2022-06-18 15:12:48,829] {standard_task_runner.py:52} INFO - Started process 1910 to run task
[2022-06-18 15:12:48,832] {standard_task_runner.py:76} INFO - Running: ['airflow', 'tasks', 'run', 'analyze_json_data', 'saveToDB', '2022-06-17T00:00:00+00:00', '--job-id', '326', '--pool', 'default_pool', '--raw', '--subdir', 'DAGS_FOLDER/dagRun.py', '--cfg-path', '/tmp/tmpr6yffiae', '--error-file', '/tmp/tmppk0d4vi6']
[2022-06-18 15:12:48,834] {standard_task_runner.py:77} INFO - Job 326: Subtask saveToDB
[2022-06-18 15:12:48,867] {logging_mixin.py:104} INFO - Running <TaskInstance: analyze_json_data.saveToDB 2022-06-17T00:00:00+00:00 [running]> on host 1189a6233bd7
[2022-06-18 15:12:48,893] {taskinstance.py:1257} INFO - Exporting the following env vars:
AIRFLOW_CTX_DAG_OWNER=Renato_Otescu
AIRFLOW_CTX_DAG_ID=analyze_json_data
AIRFLOW_CTX_TASK_ID=saveToDB
AIRFLOW_CTX_EXECUTION_DATE=2022-06-17T00:00:00+00:00
AIRFLOW_CTX_DAG_RUN_ID=scheduled__2022-06-17T00:00:00+00:00
[2022-06-18 15:12:48,921] {base_aws.py:362} INFO - Airflow Connection: aws_conn_id=aws_default
[2022-06-18 15:12:48,922] {crypto.py:82} WARNING - empty cryptography key - values will not be stored encrypted.
[2022-06-18 15:12:48,922] {base_aws.py:171} INFO - Credentials retrieved from extra_config['s3_config_file']
[2022-06-18 15:12:48,922] {base_aws.py:81} INFO - Creating session with aws_access_key_id=AKIA2RNRZHIUSS5EYBCG region_name=None
[2022-06-18 15:12:48,930] {base_aws.py:151} INFO - role_arn is None
[2022-06-18 15:12:50,597] {taskinstance.py:1455} ERROR - S3ServiceException:Access Denied,Status 403,Error AccessDenied,Rid W7TSSMMJK8CT97AS,ExtRid GtNjGJfPbMkpJ/2buX9vdo2V0z+vcI4mvEsKqf6fg7wxnhugVjyc6rTx/XLdHb7o9VfSETBbg6w=,CanRetry 1
DETAIL:  
  -----------------------------------------------
  error:  S3ServiceException:Access Denied,Status 403,Error AccessDenied,Rid W7TSSMMJK8CT97AS,ExtRid GtNjGJfPbMkpJ/2buX9vdo2V0z+vcI4mvEsKqf6fg7wxnhugVjyc6rTx/XLdHb7o9VfSETBbg6w=,CanRetry 1
  code:      8001
  context:   S3 key being read : s3://airflow-raw/results.csv
  query:     1129480
  location:  copy_s3_scanner.cpp:301
  process:   query0_124_1129480 [pid=27648]
  -----------------------------------------------

Traceback (most recent call last):
  File "/home/airflow/.local/lib/python3.6/site-packages/airflow/models/taskinstance.py", line 1112, in _run_raw_task
    self._prepare_and_execute_task_with_callbacks(context, task)
  File "/home/airflow/.local/lib/python3.6/site-packages/airflow/models/taskinstance.py", line 1285, in _prepare_and_execute_task_with_callbacks
    result = self._execute_task(context, task_copy)
  File "/home/airflow/.local/lib/python3.6/site-packages/airflow/models/taskinstance.py", line 1315, in _execute_task
    result = task_copy.execute(context=context)
  File "/home/airflow/.local/lib/python3.6/site-packages/airflow/operators/python.py", line 117, in execute
    return_value = self.execute_callable()
  File "/home/airflow/.local/lib/python3.6/site-packages/airflow/operators/python.py", line 128, in execute_callable
    return self.python_callable(*self.op_args, **self.op_kwargs)
  File "/opt/airflow/dags/dagRun.py", line 270, in uploadToDB
    cursor.execute(sql)
psycopg2.errors.InternalError_: S3ServiceException:Access Denied,Status 403,Error AccessDenied,Rid W7TSSMMJK8CT97AS,ExtRid GtNjGJfPbMkpJ/2buX9vdo2V0z+vcI4mvEsKqf6fg7wxnhugVjyc6rTx/XLdHb7o9VfSETBbg6w=,CanRetry 1
DETAIL:  
  -----------------------------------------------
  error:  S3ServiceException:Access Denied,Status 403,Error AccessDenied,Rid W7TSSMMJK8CT97AS,ExtRid GtNjGJfPbMkpJ/2buX9vdo2V0z+vcI4mvEsKqf6fg7wxnhugVjyc6rTx/XLdHb7o9VfSETBbg6w=,CanRetry 1
  code:      8001
  context:   S3 key being read : s3://airflow-raw/results.csv
  query:     1129480
  location:  copy_s3_scanner.cpp:301
  process:   query0_124_1129480 [pid=27648]
  -----------------------------------------------


[2022-06-18 15:12:50,599] {taskinstance.py:1503} INFO - Marking task as FAILED. dag_id=analyze_json_data, task_id=saveToDB, execution_date=20220617T000000, start_date=20220618T151248, end_date=20220618T151250
[2022-06-18 15:12:50,646] {local_task_job.py:146} INFO - Task exited with return code 1
