[2022-04-19 15:06:34,825] {taskinstance.py:851} INFO - Dependencies all met for <TaskInstance: analyze_json_data.saveToDB 2022-04-19T15:05:10.267375+00:00 [queued]>
[2022-04-19 15:06:34,837] {taskinstance.py:851} INFO - Dependencies all met for <TaskInstance: analyze_json_data.saveToDB 2022-04-19T15:05:10.267375+00:00 [queued]>
[2022-04-19 15:06:34,837] {taskinstance.py:1042} INFO - 
--------------------------------------------------------------------------------
[2022-04-19 15:06:34,837] {taskinstance.py:1043} INFO - Starting attempt 3 of 4
[2022-04-19 15:06:34,837] {taskinstance.py:1044} INFO - 
--------------------------------------------------------------------------------
[2022-04-19 15:06:34,843] {taskinstance.py:1063} INFO - Executing <Task(PythonOperator): saveToDB> on 2022-04-19T15:05:10.267375+00:00
[2022-04-19 15:06:34,847] {standard_task_runner.py:52} INFO - Started process 8161 to run task
[2022-04-19 15:06:34,850] {standard_task_runner.py:76} INFO - Running: ['airflow', 'tasks', 'run', 'analyze_json_data', 'saveToDB', '2022-04-19T15:05:10.267375+00:00', '--job-id', '226', '--pool', 'default_pool', '--raw', '--subdir', 'DAGS_FOLDER/dagRun.py', '--cfg-path', '/tmp/tmp46xoahv8', '--error-file', '/tmp/tmpmewltdfp']
[2022-04-19 15:06:34,852] {standard_task_runner.py:77} INFO - Job 226: Subtask saveToDB
[2022-04-19 15:06:34,880] {logging_mixin.py:104} INFO - Running <TaskInstance: analyze_json_data.saveToDB 2022-04-19T15:05:10.267375+00:00 [running]> on host 79776f5a39da
[2022-04-19 15:06:34,905] {taskinstance.py:1257} INFO - Exporting the following env vars:
AIRFLOW_CTX_DAG_OWNER=anhlbt
AIRFLOW_CTX_DAG_ID=analyze_json_data
AIRFLOW_CTX_TASK_ID=saveToDB
AIRFLOW_CTX_EXECUTION_DATE=2022-04-19T15:05:10.267375+00:00
AIRFLOW_CTX_DAG_RUN_ID=manual__2022-04-19T15:05:10.267375+00:00
[2022-04-19 15:06:34,936] {base_aws.py:362} INFO - Airflow Connection: aws_conn_id=aws_default
[2022-04-19 15:06:34,936] {crypto.py:82} WARNING - empty cryptography key - values will not be stored encrypted.
[2022-04-19 15:06:34,937] {base_aws.py:171} INFO - Credentials retrieved from extra_config['s3_config_file']
[2022-04-19 15:06:34,937] {base_aws.py:81} INFO - Creating session with aws_access_key_id=AKIA2RNRZHIUSS5EYBCG region_name=None
[2022-04-19 15:06:34,945] {base_aws.py:151} INFO - role_arn is None
[2022-04-19 15:06:36,417] {taskinstance.py:1455} ERROR - S3ServiceException:Access Denied,Status 403,Error AccessDenied,Rid KHZ0YE1S4KQ2PMBA,ExtRid 8CzvDzJQEV6I7bTSwgtLfk5bFcaPjc+P8t0smS4jopmsj0BpyKoVWSV7zPBKNrDiC/twMtPtH+w=,CanRetry 1
DETAIL:  
  -----------------------------------------------
  error:  S3ServiceException:Access Denied,Status 403,Error AccessDenied,Rid KHZ0YE1S4KQ2PMBA,ExtRid 8CzvDzJQEV6I7bTSwgtLfk5bFcaPjc+P8t0smS4jopmsj0BpyKoVWSV7zPBKNrDiC/twMtPtH+w=,CanRetry 1
  code:      8001
  context:   Listing bucket=airflow-raw prefix=results.csv
  query:     193076
  location:  s3_utility.cpp:662
  process:   padbmaster [pid=2966]
  -----------------------------------------------

Traceback (most recent call last):
  File "/home/airflow/.local/lib/python3.6/site-packages/airflow/models/taskinstance.py", line 1112, in _run_raw_task
    self._prepare_and_execute_task_with_callbacks(context, task)
  File "/home/airflow/.local/lib/python3.6/site-packages/airflow/models/taskinstance.py", line 1285, in _prepare_and_execute_task_with_callbacks
    result = self._execute_task(context, task_copy)
  File "/home/airflow/.local/lib/python3.6/site-packages/airflow/models/taskinstance.py", line 1315, in _execute_task
    result = task_copy.execute(context=context)
  File "/home/airflow/.local/lib/python3.6/site-packages/airflow/operators/python.py", line 117, in execute
    return_value = self.execute_callable()
  File "/home/airflow/.local/lib/python3.6/site-packages/airflow/operators/python.py", line 128, in execute_callable
    return self.python_callable(*self.op_args, **self.op_kwargs)
  File "/opt/airflow/dags/dagRun.py", line 270, in uploadToDB
    cursor.execute(sql)
psycopg2.errors.InternalError_: S3ServiceException:Access Denied,Status 403,Error AccessDenied,Rid KHZ0YE1S4KQ2PMBA,ExtRid 8CzvDzJQEV6I7bTSwgtLfk5bFcaPjc+P8t0smS4jopmsj0BpyKoVWSV7zPBKNrDiC/twMtPtH+w=,CanRetry 1
DETAIL:  
  -----------------------------------------------
  error:  S3ServiceException:Access Denied,Status 403,Error AccessDenied,Rid KHZ0YE1S4KQ2PMBA,ExtRid 8CzvDzJQEV6I7bTSwgtLfk5bFcaPjc+P8t0smS4jopmsj0BpyKoVWSV7zPBKNrDiC/twMtPtH+w=,CanRetry 1
  code:      8001
  context:   Listing bucket=airflow-raw prefix=results.csv
  query:     193076
  location:  s3_utility.cpp:662
  process:   padbmaster [pid=2966]
  -----------------------------------------------


[2022-04-19 15:06:36,419] {taskinstance.py:1503} INFO - Marking task as UP_FOR_RETRY. dag_id=analyze_json_data, task_id=saveToDB, execution_date=20220419T150510, start_date=20220419T150634, end_date=20220419T150636
[2022-04-19 15:06:36,464] {local_task_job.py:146} INFO - Task exited with return code 1
