[2022-04-19 15:07:06,885] {taskinstance.py:851} INFO - Dependencies all met for <TaskInstance: analyze_json_data.saveToDB 2022-04-19T15:05:10.267375+00:00 [queued]>
[2022-04-19 15:07:06,896] {taskinstance.py:851} INFO - Dependencies all met for <TaskInstance: analyze_json_data.saveToDB 2022-04-19T15:05:10.267375+00:00 [queued]>
[2022-04-19 15:07:06,896] {taskinstance.py:1042} INFO - 
--------------------------------------------------------------------------------
[2022-04-19 15:07:06,896] {taskinstance.py:1043} INFO - Starting attempt 4 of 4
[2022-04-19 15:07:06,896] {taskinstance.py:1044} INFO - 
--------------------------------------------------------------------------------
[2022-04-19 15:07:06,902] {taskinstance.py:1063} INFO - Executing <Task(PythonOperator): saveToDB> on 2022-04-19T15:05:10.267375+00:00
[2022-04-19 15:07:06,905] {standard_task_runner.py:52} INFO - Started process 8379 to run task
[2022-04-19 15:07:06,908] {standard_task_runner.py:76} INFO - Running: ['airflow', 'tasks', 'run', 'analyze_json_data', 'saveToDB', '2022-04-19T15:05:10.267375+00:00', '--job-id', '227', '--pool', 'default_pool', '--raw', '--subdir', 'DAGS_FOLDER/dagRun.py', '--cfg-path', '/tmp/tmpjnc_eki6', '--error-file', '/tmp/tmps0v6t1in']
[2022-04-19 15:07:06,911] {standard_task_runner.py:77} INFO - Job 227: Subtask saveToDB
[2022-04-19 15:07:06,940] {logging_mixin.py:104} INFO - Running <TaskInstance: analyze_json_data.saveToDB 2022-04-19T15:05:10.267375+00:00 [running]> on host 79776f5a39da
[2022-04-19 15:07:06,965] {taskinstance.py:1257} INFO - Exporting the following env vars:
AIRFLOW_CTX_DAG_OWNER=anhlbt
AIRFLOW_CTX_DAG_ID=analyze_json_data
AIRFLOW_CTX_TASK_ID=saveToDB
AIRFLOW_CTX_EXECUTION_DATE=2022-04-19T15:05:10.267375+00:00
AIRFLOW_CTX_DAG_RUN_ID=manual__2022-04-19T15:05:10.267375+00:00
[2022-04-19 15:07:06,998] {base_aws.py:362} INFO - Airflow Connection: aws_conn_id=aws_default
[2022-04-19 15:07:06,998] {crypto.py:82} WARNING - empty cryptography key - values will not be stored encrypted.
[2022-04-19 15:07:06,999] {base_aws.py:171} INFO - Credentials retrieved from extra_config['s3_config_file']
[2022-04-19 15:07:06,999] {base_aws.py:81} INFO - Creating session with aws_access_key_id=AKIA2RNRZHIUSS5EYBCG region_name=None
[2022-04-19 15:07:07,007] {base_aws.py:151} INFO - role_arn is None
[2022-04-19 15:07:08,367] {taskinstance.py:1455} ERROR - S3ServiceException:Access Denied,Status 403,Error AccessDenied,Rid YS4V05GQDVCA93CV,ExtRid 1hyntCEFvd52LVaOCC2E6SEu98EFEdR7Hm68E6TSsUJXbro71DgiAllNyBfuoVnDw4U7QzcLj2o=,CanRetry 1
DETAIL:  
  -----------------------------------------------
  error:  S3ServiceException:Access Denied,Status 403,Error AccessDenied,Rid YS4V05GQDVCA93CV,ExtRid 1hyntCEFvd52LVaOCC2E6SEu98EFEdR7Hm68E6TSsUJXbro71DgiAllNyBfuoVnDw4U7QzcLj2o=,CanRetry 1
  code:      8001
  context:   Listing bucket=airflow-raw prefix=results.csv
  query:     193082
  location:  s3_utility.cpp:662
  process:   padbmaster [pid=2987]
  -----------------------------------------------

Traceback (most recent call last):
  File "/home/airflow/.local/lib/python3.6/site-packages/airflow/models/taskinstance.py", line 1112, in _run_raw_task
    self._prepare_and_execute_task_with_callbacks(context, task)
  File "/home/airflow/.local/lib/python3.6/site-packages/airflow/models/taskinstance.py", line 1285, in _prepare_and_execute_task_with_callbacks
    result = self._execute_task(context, task_copy)
  File "/home/airflow/.local/lib/python3.6/site-packages/airflow/models/taskinstance.py", line 1315, in _execute_task
    result = task_copy.execute(context=context)
  File "/home/airflow/.local/lib/python3.6/site-packages/airflow/operators/python.py", line 117, in execute
    return_value = self.execute_callable()
  File "/home/airflow/.local/lib/python3.6/site-packages/airflow/operators/python.py", line 128, in execute_callable
    return self.python_callable(*self.op_args, **self.op_kwargs)
  File "/opt/airflow/dags/dagRun.py", line 270, in uploadToDB
    cursor.execute(sql)
psycopg2.errors.InternalError_: S3ServiceException:Access Denied,Status 403,Error AccessDenied,Rid YS4V05GQDVCA93CV,ExtRid 1hyntCEFvd52LVaOCC2E6SEu98EFEdR7Hm68E6TSsUJXbro71DgiAllNyBfuoVnDw4U7QzcLj2o=,CanRetry 1
DETAIL:  
  -----------------------------------------------
  error:  S3ServiceException:Access Denied,Status 403,Error AccessDenied,Rid YS4V05GQDVCA93CV,ExtRid 1hyntCEFvd52LVaOCC2E6SEu98EFEdR7Hm68E6TSsUJXbro71DgiAllNyBfuoVnDw4U7QzcLj2o=,CanRetry 1
  code:      8001
  context:   Listing bucket=airflow-raw prefix=results.csv
  query:     193082
  location:  s3_utility.cpp:662
  process:   padbmaster [pid=2987]
  -----------------------------------------------


[2022-04-19 15:07:08,369] {taskinstance.py:1503} INFO - Marking task as FAILED. dag_id=analyze_json_data, task_id=saveToDB, execution_date=20220419T150510, start_date=20220419T150706, end_date=20220419T150708
[2022-04-19 15:07:08,401] {local_task_job.py:146} INFO - Task exited with return code 1
