[2022-06-25 09:12:51,100] {taskinstance.py:851} INFO - Dependencies all met for <TaskInstance: analyze_json_data.saveToDB 2022-06-24T00:00:00+00:00 [queued]>
[2022-06-25 09:12:51,113] {taskinstance.py:851} INFO - Dependencies all met for <TaskInstance: analyze_json_data.saveToDB 2022-06-24T00:00:00+00:00 [queued]>
[2022-06-25 09:12:51,113] {taskinstance.py:1042} INFO - 
--------------------------------------------------------------------------------
[2022-06-25 09:12:51,113] {taskinstance.py:1043} INFO - Starting attempt 2 of 4
[2022-06-25 09:12:51,113] {taskinstance.py:1044} INFO - 
--------------------------------------------------------------------------------
[2022-06-25 09:12:51,119] {taskinstance.py:1063} INFO - Executing <Task(PythonOperator): saveToDB> on 2022-06-24T00:00:00+00:00
[2022-06-25 09:12:51,123] {standard_task_runner.py:52} INFO - Started process 1659 to run task
[2022-06-25 09:12:51,125] {standard_task_runner.py:76} INFO - Running: ['airflow', 'tasks', 'run', 'analyze_json_data', 'saveToDB', '2022-06-24T00:00:00+00:00', '--job-id', '358', '--pool', 'default_pool', '--raw', '--subdir', 'DAGS_FOLDER/dagRun.py', '--cfg-path', '/tmp/tmp4vl1e7mk', '--error-file', '/tmp/tmpd0l_zz04']
[2022-06-25 09:12:51,128] {standard_task_runner.py:77} INFO - Job 358: Subtask saveToDB
[2022-06-25 09:12:51,158] {logging_mixin.py:104} INFO - Running <TaskInstance: analyze_json_data.saveToDB 2022-06-24T00:00:00+00:00 [running]> on host bb303642214a
[2022-06-25 09:12:51,187] {taskinstance.py:1257} INFO - Exporting the following env vars:
AIRFLOW_CTX_DAG_OWNER=Renato_Otescu
AIRFLOW_CTX_DAG_ID=analyze_json_data
AIRFLOW_CTX_TASK_ID=saveToDB
AIRFLOW_CTX_EXECUTION_DATE=2022-06-24T00:00:00+00:00
AIRFLOW_CTX_DAG_RUN_ID=scheduled__2022-06-24T00:00:00+00:00
[2022-06-25 09:12:51,218] {base_aws.py:362} INFO - Airflow Connection: aws_conn_id=aws_default
[2022-06-25 09:12:51,219] {crypto.py:82} WARNING - empty cryptography key - values will not be stored encrypted.
[2022-06-25 09:12:51,219] {base_aws.py:171} INFO - Credentials retrieved from extra_config['s3_config_file']
[2022-06-25 09:12:51,219] {base_aws.py:81} INFO - Creating session with aws_access_key_id=AKIA2RNRZHIUSS5EYBCG region_name=None
[2022-06-25 09:12:51,228] {base_aws.py:151} INFO - role_arn is None
[2022-06-25 09:12:52,739] {taskinstance.py:1455} ERROR - S3ServiceException:Access Denied,Status 403,Error AccessDenied,Rid 8EF9CK4WG7FJW2JQ,ExtRid iyAZ59MvmhmjL6hFOWk1rH/A2BuCUFkP9FXIcz4YuC1ALGI0VA1Zg7MLz5rXIPKMCqJd0iX1zGc=,CanRetry 1
DETAIL:  
  -----------------------------------------------
  error:  S3ServiceException:Access Denied,Status 403,Error AccessDenied,Rid 8EF9CK4WG7FJW2JQ,ExtRid iyAZ59MvmhmjL6hFOWk1rH/A2BuCUFkP9FXIcz4YuC1ALGI0VA1Zg7MLz5rXIPKMCqJd0iX1zGc=,CanRetry 1
  code:      8001
  context:   S3 key being read : s3://airflow-raw/results.csv
  query:     1232203
  location:  copy_s3_scanner.cpp:301
  process:   query0_123_1232203 [pid=13187]
  -----------------------------------------------

Traceback (most recent call last):
  File "/home/airflow/.local/lib/python3.6/site-packages/airflow/models/taskinstance.py", line 1112, in _run_raw_task
    self._prepare_and_execute_task_with_callbacks(context, task)
  File "/home/airflow/.local/lib/python3.6/site-packages/airflow/models/taskinstance.py", line 1285, in _prepare_and_execute_task_with_callbacks
    result = self._execute_task(context, task_copy)
  File "/home/airflow/.local/lib/python3.6/site-packages/airflow/models/taskinstance.py", line 1315, in _execute_task
    result = task_copy.execute(context=context)
  File "/home/airflow/.local/lib/python3.6/site-packages/airflow/operators/python.py", line 117, in execute
    return_value = self.execute_callable()
  File "/home/airflow/.local/lib/python3.6/site-packages/airflow/operators/python.py", line 128, in execute_callable
    return self.python_callable(*self.op_args, **self.op_kwargs)
  File "/opt/airflow/dags/dagRun.py", line 270, in uploadToDB
    cursor.execute(sql)
psycopg2.errors.InternalError_: S3ServiceException:Access Denied,Status 403,Error AccessDenied,Rid 8EF9CK4WG7FJW2JQ,ExtRid iyAZ59MvmhmjL6hFOWk1rH/A2BuCUFkP9FXIcz4YuC1ALGI0VA1Zg7MLz5rXIPKMCqJd0iX1zGc=,CanRetry 1
DETAIL:  
  -----------------------------------------------
  error:  S3ServiceException:Access Denied,Status 403,Error AccessDenied,Rid 8EF9CK4WG7FJW2JQ,ExtRid iyAZ59MvmhmjL6hFOWk1rH/A2BuCUFkP9FXIcz4YuC1ALGI0VA1Zg7MLz5rXIPKMCqJd0iX1zGc=,CanRetry 1
  code:      8001
  context:   S3 key being read : s3://airflow-raw/results.csv
  query:     1232203
  location:  copy_s3_scanner.cpp:301
  process:   query0_123_1232203 [pid=13187]
  -----------------------------------------------


[2022-06-25 09:12:52,741] {taskinstance.py:1503} INFO - Marking task as UP_FOR_RETRY. dag_id=analyze_json_data, task_id=saveToDB, execution_date=20220624T000000, start_date=20220625T091251, end_date=20220625T091252
[2022-06-25 09:12:52,779] {local_task_job.py:146} INFO - Task exited with return code 1
